Workbook

Sheet All_India_Index_Upto_April23 (1
A1: Sector | B1: Year | C1: Month | D1: Date | E1: Cereals and products | F1: Meat and fish | G1: Egg | H1: Milk and products | I1: Oils and fats | J1: Fruits | K1: Vegetables | L1: Pulses and products | M1: Sugar and Confectionery | N1: Spices | O1: Non-alcoholic beverages | P1: Prepared meals, snacks, sweets etc. | Q1: Food and beverages | R1: Pan, tobacco and intoxicants | S1: Clothing | T1: Footwear | U1: Clothing and footwear | V1: Housing | W1: Fuel and light | X1: Household goods and services | Y1: Health | Z1: Transport and communication | AA1: Recreation and amusement | AB1: Education | AC1: Personal care and effects | AD1: Miscellaneous | AE1: General index
A2: Rural | B2: 2013 | C2: January | D2: =DATE(All_India_Index_Upto_April23__1___1[[#This Row],[Year]],MATCH(All_India_Index_Upto_April23__1___1[[#This Row],[Month]],{"January","February","March","April","May","June","July","August","September","October","November","December"},0),1) -> 41275 | E2: 107.5 | F2: 106.3 | G2: 108.1 | H2: 104.9 | I2: 106.1 | J2: 103.9 | K2: 101.9 | L2: 106.1 | M2: 106.8 | N2: 103.1 | O2: 104.8 | P2: 106.7 | Q2: 105.5 | R2: 105.1 | S2: 106.5 | T2: 105.8 | U2: 106.4 | W2: 105.5 | X2: 104.8 | Y2: 104 | Z2: 103.3 | AA2: 103.4 | AB2: 103.8 | AC2: 104.7 | AD2: 104 | AE2: 105.1
A3: Urban | B3: 2013 | C3: January | D3: =DATE(All_India_Index_Upto_April23__1___1[[#This Row],[Year]],MATCH(All_India_Index_Upto_April23__1___1[[#This Row],[Month]],{"January","February","March","April","May","June","July","August","September","October","November","December"},0),1) -> 41275 | E3: 110.5 | F3: 109.1 | G3: 113 | H3: 103.6 | I3: 103.4 | J3: 102.3 | K3: 102.9 | L3: 105.8 | M3: 105.1 | N3: 101.8 | O3: 105.1 | P3: 107.9 | Q3: 105.9 | R3: 105.2 | S3: 105.9 | T3: 105 | U3: 105.8 | V3: 100.3 | W3: 105.4 | X3: 104.8 | Y3: 104.1 | Z3: 103.2 | AA3: 102.9 | AB3: 103.5 | AC3: 104.3 | AD3: 103.7 | AE3: 104
A4: Rural | B4: 2013 | C4: February | D4: =DATE(All_India_Index_Upto_April23__1___1[[#This Row],[Year]],MATCH(All_India_Index_Upto_April23__1___1[[#This Row],[Month]],{"January","February","March","April","May","June","July","August","September","October","November","December"},0),1) -> 41306 | E4: 109.2 | F4: 108.7 | G4: 110.2 | H4: 105.4 | I4: 106.7 | J4: 104 | K4: 102.4 | L4: 105.9 | M4: 105.7 | N4: 103.1 | O4: 105.1 | P4: 107.7 | Q4: 106.3 | R4: 105.6 | S4: 107.1 | T4: 106.3 | U4: 107 | W4: 106.2 | X4: 105.2 | Y4: 104.4 | Z4: 103.9 | AA4: 104 | AB4: 104.1 | AC4: 104.6 | AD4: 104.4 | AE4: 105.8
A5: Urban | B5: 2013 | C5: February | D5: =DATE(All_India_Index_Upto_April23__1___1[[#This Row],[Year]],MATCH(All_India_Index_Upto_April23__1___1[[#This Row],[Month]],{"January","February","March","April","May","June","July","August","September","October","November","December"},0),1) -> 41306 | E5: 112.9 | F5: 112.9 | G5: 116.9 | H5: 104 | I5: 103.5 | J5: 103.1 | K5: 104.9 | L5: 104.1 | M5: 103.8 | N5: 102.3 | O5: 106 | P5: 109 | Q5: 107.2 | R5: 106 | S5: 106.6 | T5: 105.5 | U5: 106.4 | V5: 100.4 | W5: 105.7 | X5: 105.2 | Y5: 104.7 | Z5: 104.4 | AA5: 103.3 | AB5: 103.7 | AC5: 104.3 | AD5: 104.3 | AE5: 104.7
A6: Rural | B6: 2013 | C6: March | D6: =DATE(All_India_Index_Upto_April23__1___1[[#This Row],[Year]],MATCH(All_India_Index_Upto_April23__1___1[[#This Row],[Month]],{"January","February","March","April","May","June","July","August","September","October","November","December"},0),1) -> 41334 | E6: 110.2 | F6: 108.8 | G6: 109.9 | H6: 105.6 | I6: 106.2 | J6: 105.7 | K6: 101.4 | L6: 105.7 | M6: 105 | N6: 103.3 | O6: 105.6 | P6: 108.2 | Q6: 106.6 | R6: 106.5 | S6: 107.6 | T6: 106.8 | U6: 107.5 | W6: 106.1 | X6: 105.6 | Y6: 104.7 | Z6: 104.6 | AA6: 104 | AB6: 104.3 | AC6: 104.3 | AD6: 104.6 | AE6: 106
A7: Urban | B7: 2013 | C7: March | D7: =DATE(All_India_Index_Upto_April23__1___1[[#This Row],[Year]],MATCH(All_India_Index_Upto_April23__1___1[[#This Row],[Month]],{"January","February","March","April","May","June","July","August","September","October","November","December"},0),1) -> 41334 | E7: 113.9 | F7: 111.4 | G7: 113.2 | H7: 104.3 | I7: 102.7 | J7: 104.9 | K7: 103.8 | L7: 103.5 | M7: 102.6 | N7: 102.4 | O7: 107 | P7: 109.8 | Q7: 107.3 | R7: 106.8 | S7: 107.2 | T7: 106 | U7: 107 | V7: 100.4 | W7: 106 | X7: 105.7 | Y7: 105.2 | Z7: 105.5 | AA7: 103.5 | AB7: 103.8 | AC7: 104.2 | AD7: 104.9 | AE7: 105
A8: Rural | B8: 2013 | C8: April | D8: =DATE(All_India_Index_Upto_April23__1___1[[#This Row],[Year]],MATCH(All_India_Index_Upto_April23__1___1[[#This Row],[Month]],{"January","February","March","April","May","June","July","August","September","October","November","December"},0),1) -> 41365 | E8: 110.2 | F8: 109.5 | G8: 106.9 | H8: 106.3 | I8: 105.7 | J8: 108.3 | K8: 103.4 | L8: 105.7 | M8: 104.2 | N8: 103.2 | O8: 106.5 | P8: 108.8 | Q8: 107.1 | R8: 107.1 | S8: 108.1 | T8: 107.4 | U8: 108 | W8: 106.5 | X8: 106.1 | Y8: 105.1 | Z8: 104.4 | AA8: 104.5 | AB8: 104.8 | AC8: 102.7 | AD8: 104.6 | AE8: 106.4
A9: Urban | B9: 2013 | C9: April | D9: =DATE(All_India_Index_Upto_April23__1___1[[#This Row],[Year]],MATCH(All_India_Index_Upto_April23__1___1[[#This Row],[Month]],{"January","February","March","April","May","June","July","August","September","October","November","December"},0),1) -> 41365 | E9: 114.6 | F9: 113.4 | G9: 106 | H9: 104.7 | I9: 102.1 | J9: 109.5 | K9: 109.7 | L9: 104.6 | M9: 102 | N9: 103.5 | O9: 108.2 | P9: 110.6 | Q9: 108.8 | R9: 108.5 | S9: 107.9 | T9: 106.4 | U9: 107.7 | V9: 100.5 | W9: 106.4 | X9: 106.5 | Y9: 105.7 | Z9: 105 | AA9: 104 | AB9: 105.2 | AC9: 103.2 | AD9: 105.1 | AE9: 105.7
A10: Rural | B10: 2013 | C10: May | D10: =DATE(All_India_Index_Upto_April23__1___1[[#This Row],[Year]],MATCH(All_India_Index_Upto_April23__1___1[[#This Row],[Month]],{"January","February","March","April","May","June","July","August","September","October","November","December"},0),1) -> 41395 | E10: 110.9 | F10: 109.8 | G10: 105.9 | H10: 107.5 | I10: 105.3 | J10: 108.1 | K10: 107.3 | L10: 106.1 | M10: 103.7 | N10: 104 | O10: 107.4 | P10: 109.9 | Q10: 108.1 | R10: 108.1 | S10: 108.8 | T10: 107.9 | U10: 108.6 | W10: 107.5 | X10: 106.8 | Y10: 105.7 | Z10: 104.1 | AA10: 105 | AB10: 105.5 | AC10: 102.1 | AD10: 104.8 | AE10: 107.2
A11: Urban | B11: 2013 | C11: May | D11: =DATE(All_India_Index_Upto_April23__1___1[[#This Row],[Year]],MATCH(All_India_Index_Upto_April23__1___1[[#This Row],[Month]],{"January","February","March","April","May","June","July","August","September","October","November","December"},0),1) -> 41395 | E11: 115.4 | F11: 114.2 | G11: 102.7 | H11: 105.5 | I11: 101.5 | J11: 110.6 | K11: 123.7 | L11: 105.2 | M11: 101.9 | N11: 105 | O11: 109.1 | P11: 111.3 | Q11: 111.1 | R11: 109.8 | S11: 108.5 | T11: 106.7 | U11: 108.3 | V11: 100.5 | W11: 107.2 | X11: 107.1 | Y11: 106.2 | Z11: 103.9 | AA11: 104.6 | AB11: 105.7 | AC11: 102.6 | AD11: 104.9 | AE11: 106.6
A12: Rural | B12: 2013 | C12: June | D12: =DATE(All_India_Index_Upto_April23__1___1[[#This Row],[Year]],MATCH(All_India_Index_Upto_April23__1___1[[#This Row],[Month]],{"January","February","March","April","May","June","July","August","September","October","November","December"},0),1) -> 41426 | E12: 112.3 | F12: 112.1 | G12: 108.1 | H12: 108.3 | I12: 105.9 | J12: 109.2 | K12: 118 | L12: 106.8 | M12: 104.1 | N12: 105.4 | O12: 108.2 | P12: 111 | Q12: 110.6 | R12: 109 | S12: 109.7 | T12: 108.8 | U12: 109.5 | W12: 108.5 | X12: 107.5 | Y12: 106.3 | Z12: 105 | AA12: 105.6 | AB12: 106.5 | AC12: 102.5 | AD12: 105.5 | AE12: 108.9
A13: Urban | B13: 2013 | C13: June | D13: =DATE(All_India_Index_Upto_April23__1___1[[#This Row],[Year]],MATCH(All_India_Index_Upto_April23__1___1[[#This Row],[Month]],{"January","February","March","April","May","June","July","August","September","October","November","December"},0),1) -> 41426 | E13: 117 | F13: 120.1 | G13: 112.5 | H13: 107.3 | I13: 101.3 | J13: 112.4 | K13: 143.6 | L13: 105.4 | M13: 101.4 | N13: 106.4 | O13: 110 | P13: 112.2 | Q13: 115 | R13: 110.9 | S13: 109.2 | T13: 107.2 | U13: 108.9 | V13: 106.6 | W13: 108 | X13: 107.7 | Y13: 106.5 | Z13: 105.2 | AA13: 105.2 | AB13: 108.1 | AC13: 103.3 | AD13: 106.1 | AE13: 109.7
A14: Rural | B14: 2013 | C14: July | D14: =DATE(All_India_Index_Upto_April23__1___1[[#This Row],[Year]],MATCH(All_India_Index_Upto_April23__1___1[[#This Row],[Month]],{"January","February","March","April","May","June","July","August","September","October","November","December"},0),1) -> 41456 | E14: 113.4 | F14: 114.9 | G14: 110.5 | H14: 109.3 | I14: 106.2 | J14: 110.3 | K14: 129.2 | L14: 107.1 | M14: 104.3 | N14: 106.4 | O14: 109.1 | P14: 112.1 | Q14: 113.1 | R14: 109.8 | S14: 110.5 | T14: 109.5 | U14: 110.3 | W14: 109.5 | X14: 108.3 | Y14: 106.9 | Z14: 106.8 | AA14: 106.4 | AB14: 107.8 | AC14: 102.5 | AD14: 106.5 | AE14: 110.7
A15: Urban | B15: 2013 | C15: July | D15: =DATE(All_India_Index_Upto_April23__1___1[[#This Row],[Year]],MATCH(All_India_Index_Upto_April23__1___1[[#This Row],[Month]],{"January","February","March","April","May","June","July","August","September","October","November","December"},0),1) -> 41456 | E15: 117.8 | F15: 119.2 | G15: 114 | H15: 108.3 | I15: 101.1 | J15: 113.2 | K15: 160.9 | L15: 105.1 | M15: 101.3 | N15: 107.5 | O15: 110.4 | P15: 113.1 | Q15: 117.5 | R15: 111.7 | S15: 109.8 | T15: 107.8 | U15: 109.5 | V15: 107.7 | W15: 108.6 | X15: 108.1 | Y15: 107.1 | Z15: 107.3 | AA15: 105.9 | AB15: 110.1 | AC15: 103.2 | AD15: 107.3 | AE15: 111.4
A16: Rural | B16: 2013 | C16: August | D16: =DATE(All_India_Index_Upto_April23__1___1[[#This Row],[Year]],MATCH(All_India_Index_Upto_April23__1___1[[#This Row],[Month]],{"January","February","March","April","May","June","July","August","September","October","November","December"},0),1) -> 41487 | E16: 114.3 | F16: 115.4 | G16: 111.1 | H16: 110 | I16: 106.4 | J16: 110.8 | K16: 138.9 | L16: 107.4 | M16: 104.1 | N16: 106.9 | O16: 109.7 | P16: 112.6 | Q16: 114.9 | R16: 110.7 | S16: 111.3 | T16: 110.2 | U16: 111.1 | W16: 109.9 | X16: 108.7 | Y16: 107.5 | Z16: 107.8 | AA16: 106.8 | AB16: 108.7 | AC16: 105 | AD16: 107.5 | AE16: 112.1
A17: Urban | B17: 2013 | C17: August | D17: =DATE(All_India_Index_Upto_April23__1___1[[#This Row],[Year]],MATCH(All_India_Index_Upto_April23__1___1[[#This Row],[Month]],{"January","February","March","April","May","June","July","August","September","October","November","December"},0),1) -> 41487 | E17: 118.3 | F17: 120.4 | G17: 112.7 | H17: 108.9 | I17: 101.1 | J17: 108.7 | K17: 177 | L17: 104.7 | M17: 101 | N17: 108.5 | O17: 110.9 | P17: 114.3 | Q17: 119.6 | R17: 112.4 | S17: 110.6 | T17: 108.3 | U17: 110.2 | V17: 108.9 | W17: 109.3 | X17: 108.7 | Y17: 107.6 | Z17: 108.1 | AA17: 106.5 | AB17: 110.8 | AC17: 106 | AD17: 108.3 | AE17: 112.7
A18: Rural | B18: 2013 | C18: September | D18: =DATE(All_India_Index_Upto_April23__1___1[[#This Row],[Year]],MATCH(All_India_Index_Upto_April23__1___1[[#This Row],[Month]],{"January","February","March","April","May","June","July","August","September","October","November","December"},0),1) -> 41518 | E18: 115.4 | F18: 115.7 | G18: 111.7 | H18: 111 | I18: 107.4 | J18: 110.9 | K18: 154 | L18: 108.1 | M18: 104.2 | N18: 107.9 | O18: 110.4 | P18: 114 | Q18: 117.8 | R18: 111.7 | S18: 112.7 | T18: 111.4 | U18: 112.5 | W18: 111.1 | X18: 109.6 | Y18: 108.3 | Z18: 109.3 | AA18: 107.7 | AB18: 109.8 | AC18: 106.7 | AD18: 108.7 | AE18: 114.2
A19: Urban | B19: 2013 | C19: September | D19: =DATE(All_India_Index_Upto_April23__1___1[[#This Row],[Year]],MATCH(All_India_Index_Upto_April23__1___1[[#This Row],[Month]],{"January","February","March","April","May","June","July","August","September","October","November","December"},0),1) -> 41518 | E19: 118.6 | F19: 119.1 | G19: 113.2 | H19: 109.6 | I19: 101.7 | J19: 103.2 | K19: 174.3 | L19: 105.1 | M19: 100.8 | N19: 109.1 | O19: 111.1 | P19: 115.4 | Q19: 119.2 | R19: 112.9 | S19: 111.4 | T19: 109 | U19: 111.1 | V19: 109.7 | W19: 109.5 | X19: 109.6 | Y19: 107.9 | Z19: 110.4 | AA19: 107.4 | AB19: 111.2 | AC19: 106.9 | AD19: 109.4 | AE19: 113.2
A20: Rural | B20: 2013 | C20: October | D20: =DATE(All_India_Index_Upto_April23__1___1[[#This Row],[Year]],MATCH(All_India_Index_Upto_April23__1___1[[#This Row],[Month]],{"January","February","March","April","May","June","July","August","September","October","November","December"},0),1) -> 41548 | E20: 116.3 | F20: 115.4 | G20: 112.6 | H20: 111.7 | I20: 107.7 | J20: 113.2 | K20: 164.9 | L20: 108.3 | M20: 103.9 | N20: 108.2 | O20: 111.1 | P20: 114.9 | Q20: 119.8 | R20: 112.2 | S20: 113.6 | T20: 112.3 | U20: 113.4 | W20: 111.6 | X20: 110.4 | Y20: 108.9 | Z20: 109.3 | AA20: 108.3 | AB20: 110.2 | AC20: 107.5 | AD20: 109.1 | AE20: 115.5
A21: Urban | B21: 2013 | C21: October | D21: =DATE(All_India_Index_Upto_April23__1___1[[#This Row],[Year]],MATCH(All_India_Index_Upto_April23__1___1[[#This Row],[Month]],{"January","February","March","April","May","June","July","August","September","October","November","December"},0),1) -> 41548 | E21: 118.9 | F21: 118.1 | G21: 114.5 | H21: 110.4 | I21: 102.3 | J21: 106.2 | K21: 183.5 | L21: 105.3 | M21: 100.2 | N21: 109.6 | O21: 111.4 | P21: 116 | Q21: 120.8 | R21: 113.5 | S21: 112.5 | T21: 109.7 | U21: 112 | V21: 110.5 | W21: 109.7 | X21: 110.2 | Y21: 108.2 | Z21: 109.7 | AA21: 108 | AB21: 111.3 | AC21: 107.3 | AD21: 109.4 | AE21: 114
A22: Urban | B22: 2013 | C22: November | D22: =DATE(All_India_Index_Upto_April23__1___1[[#This Row],[Year]],MATCH(All_India_Index_Upto_April23__1___1[[#This Row],[Month]],{"January","February","March","April","May","June","July","August","September","October","November","December"},0),1) -> 41579 | E22: 119.8 | F22: 116.3 | G22: 122.6 | H22: 112 | I22: 103.2 | J22: 110 | K22: 192.8 | L22: 106.3 | M22: 99.5 | N22: 110.3 | O22: 111.8 | P22: 117.1 | Q22: 122.9 | R22: 114.1 | S22: 113.5 | T22: 110.3 | U22: 113 | V22: 111.1 | W22: 110 | X22: 110.9 | Y22: 108.6 | Z22: 109.5 | AA22: 108.5 | AB22: 111.3 | AC22: 107.9 | AD22: 109.6 | AE22: 115
A23: Rural | B23: 2013 | C23: November | D23: =DATE(All_India_Index_Upto_April23__1___1[[#This Row],[Year]],MATCH(All_India_Index_Upto_April23__1___1[[#This Row],[Month]],{"January","February","March","April","May","June","July","August","September","October","November","December"},0),1) -> 41579 | E23: 117.3 | F23: 114.9 | G23: 116.2 | H23: 112.8 | I23: 108.9 | J23: 116.6 | K23: 178.1 | L23: 109.1 | M23: 103.6 | N23: 109 | O23: 111.8 | P23: 116 | Q23: 122.5 | R23: 112.8 | S23: 114.6 | T23: 113.1 | U23: 114.4 | W23: 112.6 | X23: 111.3 | Y23: 109.7 | Z23: 109.6 | AA23: 108.7 | AB23: 111 | AC23: 108.2 | AD23: 109.8 | AE23: 117.4
A24: Rural | B24: 2013 | C24: December | D24: =DATE(All_India_Index_Upto_April23__1___1[[#This Row],[Year]],MATCH(All_India_Index_Upto_April23__1___1[[#This Row],[Month]],{"January","February","March","April","May","June","July","August","September","October","November","December"},0),1) -> 41609 | E24: 118.4 | F24: 115.9 | G24: 120.4 | H24: 113.8 | I24: 109.5 | J24: 115.5 | K24: 145.7 | L24: 109.5 | M24: 102.9 | N24: 109.8 | O24: 112.1 | P24: 116.8 | Q24: 118.7 | R24: 113.6 | S24: 115.8 | T24: 114 | U24: 115.5 | W24: 112.8 | X24: 112.1 | Y24: 110.1 | Z24: 109.9 | AA24: 109.2 | AB24: 111.6 | AC24: 108.1 | AD24: 110.1 | AE24: 115.5
A25: Urban | B25: 2013 | C25: December | D25: =DATE(All_India_Index_Upto_April23__1___1[[#This Row],[Year]],MATCH(All_India_Index_Upto_April23__1___1[[#This Row],[Month]],{"January","February","March","April","May","June","July","August","September","October","November","December"},0),1) -> 41609 | E25: 120.5 | F25: 118.1 | G25: 128.5 | H25: 112.8 | I25: 103.4 | J25: 110.7 | K25: 144.8 | L25: 107.1 | M25: 98.6 | N25: 111.9 | O25: 112.1 | P25: 118.1 | Q25: 117.8 | R25: 115 | S25: 114.2 | T25: 110.9 | U25: 113.7 | V25: 110.7 | W25: 110.4 | X25: 111.3 | Y25: 109 | Z25: 109.7 | AA25: 108.9 | AB25: 111.4 | AC25: 107.7 | AD25: 109.8 | AE25: 113.3
A26: Rural+Urban | B26: 2013 | C26: January | D26: =DATE(All_India_Index_Upto_April23__1___1[[#This Row],[Year]],MATCH(All_India_Index_Upto_April23__1___1[[#This Row],[Month]],{"January","February","March","April","May","June","July","August","September","October","November","December"},0),1) -> 41275 | E26: 108.4 | F26: 107.3 | G26: 110 | H26: 104.4 | I26: 105.1 | J26: 103.2 | K26: 102.2 | L26: 106 | M26: 106.2 | N26: 102.7 | O26: 104.9 | P26: 107.3 | Q26: 105.6 | R26: 105.1 | S26: 106.3 | T26: 105.5 | U26: 106.2 | V26: 100.3 | W26: 105.5 | X26: 104.8 | Y26: 104 | Z26: 103.2 | AA26: 103.1 | AB26: 103.6 | AC26: 104.5 | AD26: 103.9 | AE26: 104.6
A27: Rural+Urban | B27: 2013 | C27: February | D27: =DATE(All_India_Index_Upto_April23__1___1[[#This Row],[Year]],MATCH(All_India_Index_Upto_April23__1___1[[#This Row],[Month]],{"January","February","March","April","May","June","July","August","September","October","November","December"},0),1) -> 41306 | E27: 110.4 | F27: 110.2 | G27: 112.8 | H27: 104.9 | I27: 105.5 | J27: 103.6 | K27: 103.2 | L27: 105.3 | M27: 105.1 | N27: 102.8 | O27: 105.5 | P27: 108.3 | Q27: 106.6 | R27: 105.7 | S27: 106.9 | T27: 106 | U27: 106.8 | V27: 100.4 | W27: 106 | X27: 105.2 | Y27: 104.5 | Z27: 104.2 | AA27: 103.6 | AB27: 103.9 | AC27: 104.5 | AD27: 104.4 | AE27: 105.3
A28: Rural+Urban | B28: 2013 | C28: March | D28: =DATE(All_India_Index_Upto_April23__1___1[[#This Row],[Year]],MATCH(All_India_Index_Upto_April23__1___1[[#This Row],[Month]],{"January","February","March","April","May","June","July","August","September","October","November","December"},0),1) -> 41334 | E28: 111.4 | F28: 109.7 | G28: 111.2 | H28: 105.1 | I28: 104.9 | J28: 105.3 | K28: 102.2 | L28: 105 | M28: 104.2 | N28: 103 | O28: 106.2 | P28: 108.9 | Q28: 106.9 | R28: 106.6 | S28: 107.4 | T28: 106.5 | U28: 107.3 | V28: 100.4 | W28: 106.1 | X28: 105.6 | Y28: 104.9 | Z28: 105.1 | AA28: 103.7 | AB28: 104 | AC28: 104.3 | AD28: 104.7 | AE28: 105.5
A29: Rural+Urban | B29: 2013 | C29: April | D29: =DATE(All_India_Index_Upto_April23__1___1[[#This Row],[Year]],MATCH(All_India_Index_Upto_April23__1___1[[#This Row],[Month]],{"January","February","March","April","May","June","July","August","September","October","November","December"},0),1) -> 41365 | E29: 111.6 | F29: 110.9 | G29: 106.6 | H29: 105.7 | I29: 104.4 | J29: 108.9 | K29: 105.5 | L29: 105.3 | M29: 103.5 | N29: 103.3 | O29: 107.2 | P29: 109.6 | Q29: 107.7 | R29: 107.5 | S29: 108 | T29: 107 | U29: 107.9 | V29: 100.5 | W29: 106.5 | X29: 106.3 | Y29: 105.3 | Z29: 104.7 | AA29: 104.2 | AB29: 105 | AC29: 102.9 | AD29: 104.8 | AE29: 106.1
A30: Rural+Urban | B30: 2013 | C30: May | D30: =DATE(All_India_Index_Upto_April23__1___1[[#This Row],[Year]],MATCH(All_India_Index_Upto_April23__1___1[[#This Row],[Month]],{"January","February","March","April","May","June","July","August","September","October","November","December"},0),1) -> 41395 | E30: 112.3 | F30: 111.3 | G30: 104.7 | H30: 106.8 | I30: 103.9 | J30: 109.3 | K30: 112.9 | L30: 105.8 | M30: 103.1 | N30: 104.3 | O30: 108.1 | P30: 110.5 | Q30: 109.2 | R30: 108.6 | S30: 108.7 | T30: 107.4 | U30: 108.5 | V30: 100.5 | W30: 107.4 | X30: 106.9 | Y30: 105.9 | Z30: 104 | AA30: 104.8 | AB30: 105.6 | AC30: 102.3 | AD30: 104.8 | AE30: 106.9
A31: Rural+Urban | B31: 2013 | C31: June | D31: =DATE(All_India_Index_Upto_April23__1___1[[#This Row],[Year]],MATCH(All_India_Index_Upto_April23__1___1[[#This Row],[Month]],{"January","February","March","April","May","June","July","August","September","October","November","December"},0),1) -> 41426 | E31: 113.8 | F31: 114.9 | G31: 109.8 | H31: 107.9 | I31: 104.2 | J31: 110.7 | K31: 126.7 | L31: 106.3 | M31: 103.2 | N31: 105.7 | O31: 109 | P31: 111.6 | Q31: 112.2 | R31: 109.5 | S31: 109.5 | T31: 108.1 | U31: 109.3 | V31: 106.6 | W31: 108.3 | X31: 107.6 | Y31: 106.4 | Z31: 105.1 | AA31: 105.4 | AB31: 107.4 | AC31: 102.8 | AD31: 105.8 | AE31: 109.3
A32: Rural+Urban | B32: 2013 | C32: July | D32: =DATE(All_India_Index_Upto_April23__1___1[[#This Row],[Year]],MATCH(All_India_Index_Upto_April23__1___1[[#This Row],[Month]],{"January","February","March","April","May","June","July","August","September","October","November","December"},0),1) -> 41456 | E32: 114.8 | F32: 116.4 | G32: 111.9 | H32: 108.9 | I32: 104.3 | J32: 111.7 | K32: 140 | L32: 106.4 | M32: 103.3 | N32: 106.8 | O32: 109.6 | P32: 112.6 | Q32: 114.7 | R32: 110.3 | S32: 110.2 | T32: 108.8 | U32: 110 | V32: 107.7 | W32: 109.2 | X32: 108.2 | Y32: 107 | Z32: 107.1 | AA32: 106.1 | AB32: 109.1 | AC32: 102.8 | AD32: 106.9 | AE32: 111
A33: Rural+Urban | B33: 2013 | C33: August | D33: =DATE(All_India_Index_Upto_April23__1___1[[#This Row],[Year]],MATCH(All_India_Index_Upto_April23__1___1[[#This Row],[Month]],{"January","February","March","April","May","June","July","August","September","October","November","December"},0),1) -> 41487 | E33: 115.6 | F33: 117.2 | G33: 111.7 | H33: 109.6 | I33: 104.5 | J33: 109.8 | K33: 151.8 | L33: 106.5 | M33: 103.1 | N33: 107.4 | O33: 110.2 | P33: 113.4 | Q33: 116.6 | R33: 111.2 | S33: 111 | T33: 109.4 | U33: 110.7 | V33: 108.9 | W33: 109.7 | X33: 108.7 | Y33: 107.5 | Z33: 108 | AA33: 106.6 | AB33: 109.9 | AC33: 105.4 | AD33: 107.9 | AE33: 112.4
A34: Rural+Urban | B34: 2013 | C34: September | D34: =DATE(All_India_Index_Upto_April23__1___1[[#This Row],[Year]],MATCH(All_India_Index_Upto_April23__1___1[[#This Row],[Month]],{"January","February","March","April","May","June","July","August","September","October","November","December"},0),1) -> 41518 | E34: 116.4 | F34: 116.9 | G34: 112.3 | H34: 110.5 | I34: 105.3 | J34: 107.3 | K34: 160.9 | L34: 107.1 | M34: 103.1 | N34: 108.3 | O34: 110.7 | P34: 114.6 | Q34: 118.3 | R34: 112 | S34: 112.2 | T34: 110.4 | U34: 111.9 | V34: 109.7 | W34: 110.5 | X34: 109.6 | Y34: 108.1 | Z34: 109.9 | AA34: 107.5 | AB34: 110.6 | AC34: 106.8 | AD34: 109 | AE34: 113.7
A35: Rural+Urban | B35: 2013 | C35: October | D35: =DATE(All_India_Index_Upto_April23__1___1[[#This Row],[Year]],MATCH(All_India_Index_Upto_April23__1___1[[#This Row],[Month]],{"January","February","March","April","May","June","July","August","September","October","November","December"},0),1) -> 41548 | E35: 117.1 | F35: 116.3 | G35: 113.3 | H35: 111.2 | I35: 105.7 | J35: 109.9 | K35: 171.2 | L35: 107.3 | M35: 102.7 | N35: 108.7 | O35: 111.2 | P35: 115.4 | Q35: 120.2 | R35: 112.5 | S35: 113.2 | T35: 111.2 | U35: 112.8 | V35: 110.5 | W35: 110.9 | X35: 110.3 | Y35: 108.6 | Z35: 109.5 | AA35: 108.1 | AB35: 110.8 | AC35: 107.4 | AD35: 109.2 | AE35: 114.8
A36: Rural+Urban | B36: 2013 | C36: November | D36: =DATE(All_India_Index_Upto_April23__1___1[[#This Row],[Year]],MATCH(All_India_Index_Upto_April23__1___1[[#This Row],[Month]],{"January","February","March","April","May","June","July","August","September","October","November","December"},0),1) -> 41579 | E36: 118.1 | F36: 115.4 | G36: 118.7 | H36: 112.5 | I36: 106.8 | J36: 113.5 | K36: 183.1 | L36: 108.2 | M36: 102.2 | N36: 109.4 | O36: 111.8 | P36: 116.5 | Q36: 122.6 | R36: 113.1 | S36: 114.2 | T36: 111.9 | U36: 113.8 | V36: 111.1 | W36: 111.6 | X36: 111.1 | Y36: 109.3 | Z36: 109.5 | AA36: 108.6 | AB36: 111.2 | AC36: 108.1 | AD36: 109.7 | AE36: 116.3
A37: Rural+Urban | B37: 2013 | C37: December | D37: =DATE(All_India_Index_Upto_April23__1___1[[#This Row],[Year]],MATCH(All_India_Index_Upto_April23__1___1[[#This Row],[Month]],{"January","February","March","April","May","June","July","August","September","October","November","December"},0),1) -> 41609 | E37: 119.1 | F37: 116.7 | G37: 123.5 | H37: 113.4 | I37: 107.3 | J37: 113.3 | K37: 145.4 | L37: 108.7 | M37: 101.5 | N37: 110.5 | O37: 112.1 | P37: 117.4 | Q37: 118.4 | R37: 114 | S37: 115.2 | T37: 112.7 | U37: 114.8 | V37: 110.7 | W37: 111.9 | X37: 111.7 | Y37: 109.7 | Z37: 109.8 | AA37: 109 | AB37: 111.5 | AC37: 107.9 | AD37: 110 | AE37: 114.5
A38: Rural | B38: 2014 | C38: January | D38: =DATE(All_India_Index_Upto_April23__1___1[[#This Row],[Year]],MATCH(All_India_Index_Upto_April23__1___1[[#This Row],[Month]],{"January","February","March","April","May","June","July","August","September","October","November","December"},0),1) -> 41640 | E38: 118.9 | F38: 117.1 | G38: 120.5 | H38: 114.4 | I38: 109 | J38: 115.5 | K38: 123.9 | L38: 109.6 | M38: 101.8 | N38: 110.2 | O38: 112.4 | P38: 117.3 | Q38: 116 | R38: 114 | S38: 116.5 | T38: 114.5 | U38: 116.2 | W38: 113 | X38: 112.6 | Y38: 110.6 | Z38: 110.5 | AA38: 109.6 | AB38: 111.8 | AC38: 108.3 | AD38: 110.6 | AE38: 114.2
A39: Urban | B39: 2014 | C39: January | D39: =DATE(All_India_Index_Upto_April23__1___1[[#This Row],[Year]],MATCH(All_India_Index_Upto_April23__1___1[[#This Row],[Month]],{"January","February","March","April","May","June","July","August","September","October","November","December"},0),1) -> 41640 | E39: 121.2 | F39: 122 | G39: 129.9 | H39: 113.6 | I39: 102.9 | J39: 112.1 | K39: 118.9 | L39: 107.5 | M39: 96.9 | N39: 112.7 | O39: 112.1 | P39: 119 | Q39: 115.5 | R39: 115.7 | S39: 114.8 | T39: 111.3 | U39: 114.3 | V39: 111.6 | W39: 111 | X39: 111.9 | Y39: 109.7 | Z39: 110.8 | AA39: 109.8 | AB39: 111.5 | AC39: 108 | AD39: 110.5 | AE39: 112.9
A40: Rural | B40: 2014 | C40: February | D40: =DATE(All_India_Index_Upto_April23__1___1[[#This Row],[Year]],MATCH(All_India_Index_Upto_April23__1___1[[#This Row],[Month]],{"January","February","March","April","May","June","July","August","September","October","November","December"},0),1) -> 41671 | E40: 119.4 | F40: 117.7 | G40: 121.2 | H40: 115 | I40: 109 | J40: 116.6 | K40: 116 | L40: 109.8 | M40: 101.1 | N40: 110.4 | O40: 112.9 | P40: 117.8 | Q40: 115.3 | R40: 114.2 | S40: 117.1 | T40: 114.5 | U40: 116.7 | W40: 113.2 | X40: 112.9 | Y40: 110.9 | Z40: 110.8 | AA40: 109.9 | AB40: 112 | AC40: 108.7 | AD40: 110.9 | AE40: 114
...

Sheet Inflation_Dashboard

Sheet Q1_Contribution_Analysis
A1: Consumer Price Index (CPI) Analysis Report
A2: Reporting Period: May 2023 | Base Year: 2012
A3: Data Source: All-India Consumer Price Index
A4: Summary
A5: This analysis studies the Consumer Price Index (CPI) for May 2023 to understand which broad areas are putting the most pressure on prices in India.We grouped 26 detailed CPI categories into 8 broader categories such as Food, Health, Energy, and Housing.The analysis shows that Health is the biggest contributor to overall price levels, followed by Clothing & Footwear and Energy.There are also clear differences between Rural and Urban areas, especially in Housing and Energy costs.
A6: Methodology (How the Analysis Was Done)
A7: Step 1: Creating Broad Categories
A8: The original CPI data has 26 individual categories.
A9: These were grouped into 8 broader buckets:
A10: Example: Cereals, Milk, Vegetables, Spices, and Prepared Meals were grouped under Food.
A11: Step 2: Calculating Bucket Index
A12: Since official CPI weights were not available, we used a simple average of all categories within each bucket.
... A19: The following table details the calculated index for each broader category and its percentage share of the analyzed basket:
A21: Bucket Name | B21: Bucket Index (Rural + Urban) | C21: Bucket Index (Rural) | D21: Bucket Index (Urban) | E21: Contribution % (Rural + Urban) | F21: Contribution % (Rural) | G21: Contribution % (Urban)
A22: Food | B22: 177.45385 | C22: 176.20769 | D22: 179.62308 | E22: 0.1241358 | F22: 0.13874028 | G22: 0.12717611
A23: Energy | B23: 182.8 | C23: 182.5 | D23: 183.4 | E23: 0.12787564 | F23: 0.14369464 | G23: 0.12985023
A24: Transport | B24: 164.8 | C24: 169.7 | D24: 160.4 | E24: 0.11528395 | F24: 0.13361633 | G24: 0.11356585
A25: Housing | B25: 175.6 | D25: 175.6 | E25: 0.12283896 | G25: 0.1243277
A26: Health | B26: 185.7 | C26: 187.8 | D26: 182.2 | E26: 0.1299043 | F26: 0.14786769 | G26: 0.12900061
A27: Education | B27: 177.1 | C27: 180.3 | D27: 174.8 | E27: 0.12388827 | F27: 0.14196243 | G27: 0.12376129
A28: Clothing & Footwear | B28: 184.4 | C28: 189.96667 | D28: 176.23333 | E28: 0.1289949 | F28: 0.14957365 | G28: 0.12477611
A29: Others | B29: 181.66 | C29: 183.58 | D29: 180.14 | E29: 0.12707817 | F29: 0.14454499 | G29: 0.1275421
A30: Total | B30: 1429.5138 | C30: 1270.0544 | D30: 1412.3964 | E30: 1 | F30: 1 | G30: 1
B31: Note: Rural Housing data is not available, so Housing is only reflected in Urban and Combined values.
A49: Key Findings
A50: A. Highest Contributor to CPI
A51: Health (13.00%) is the largest contributor to CPI.
A52: This means healthcare-related costs have increased the most compared to the 2012 base year.
A53: Rising medical expenses are the strongest inflation driver in May 2023.
A54: B. Lowest Contributor
A55: Transport and Communication (11.54%) contributes the least.
A56: This suggests that transport and communication prices have grown more slowly than other sectors.
A57: C. Rural vs Urban Differences
A58: Urban Areas:
A59: Housing, Education, and Health play a major role in inflation.
A60: Rural Areas:
... A65: As of May 2023, Health and Clothing & Footwear are the most important drivers of CPI inflation in India. The analysis also shows clear differences in inflation pressure between Rural and Urban households, especially in Housing and Energy. This grouped-bucket approach provides a clear and balanced view of inflation patterns across the economy.

Sheet Sheet6
A1: Category Name | B1: Index (Rural+Urban) | C1: Index (Rural) | D1: Index (Urban) | E1: Bucket | G1: Bucket Name | H1: Bucket Index (Rural + Urban) | I1: Bucket Index (Rural) | J1: Bucket Index (Urban) | K1: Contribution % (Rural + Urban) | L1: Contribution % (Rural) | M1: Contribution % (Urban)
A2: Cereals and products | B2: {=IFERROR( _xlfn.XLOOKUP( 1, (All_India_Index_Upto_April23__1___1[Sector]="Rural+Urban") * (All_India_Index_Upto_April23__1___1[Date]=DATE(2023,5,1)), INDEX(All_India_Index_Upto_April23__1___1[],0, MATCH($A2, All_India_Index_Upto_April23__1___1[#Headers],0) ) ), "")} -> 173.7 | C2: {=IFERROR( _xlfn.XLOOKUP( 1, (All_India_Index_Upto_April23__1___1[Sector]="Rural") * (All_India_Index_Upto_April23__1___1[Date]=DATE(2023,5,1)), INDEX(All_India_Index_Upto_April23__1___1[],0, MATCH($A2, All_India_Index_Upto_April23__1___1[#Headers],0) ) ), "")} -> 173.2 | D2: {=IFERROR( _xlfn.XLOOKUP( 1, (All_India_Index_Upto_April23__1___1[Sector]="Urban") * (All_India_Index_Upto_April23__1___1[Date]=DATE(2023,5,1)), INDEX(All_India_Index_Upto_April23__1___1[],0, MATCH($A2, All_India_Index_Upto_April23__1___1[#Headers],0) ) ), "")} -> 174.7 | E2: Food | G2: Food | H2: =AVERAGEIF($E$2:$E$27, G2, $B$2:$B$27) -> 177.45385 | I2: =IF(G2="Housing","",AVERAGEIF($E:$E, G2, $C:$C)) -> 176.20769 | J2: =AVERAGEIF($E:$E, G2, $D:$D) -> 179.62308 | K2: =H2 / SUM($H$2:$H$9) -> 0.1241358 | L2: =IF(I2="","", I2 / SUM($I$2:$I$9)) -> 0.13874028 | M2: =J2 / SUM($J$2:$J$9) -> 0.12717611
A3: Meat and fish | B3: {=IFERROR( _xlfn.XLOOKUP( 1, (All_India_Index_Upto_April23__1___1[Sector]="Rural+Urban") * (All_India_Index_Upto_April23__1___1[Date]=DATE(2023,5,1)), INDEX(All_India_Index_Upto_April23__1___1[],0, MATCH($A3, All_India_Index_Upto_April23__1___1[#Headers],0) ) ), "")} -> 214.3 | C3: {=IFERROR( _xlfn.XLOOKUP( 1, (All_India_Index_Upto_April23__1___1[Sector]="Rural") * (All_India_Index_Upto_April23__1___1[Date]=DATE(2023,5,1)), INDEX(All_India_Index_Upto_April23__1___1[],0, MATCH($A3, All_India_Index_Upto_April23__1___1[#Headers],0) ) ), "")} -> 211.5 | D3: {=IFERROR( _xlfn.XLOOKUP( 1, (All_India_Index_Upto_April23__1___1[Sector]="Urban") * (All_India_Index_Upto_April23__1___1[Date]=DATE(2023,5,1)), INDEX(All_India_Index_Upto_April23__1___1[],0, MATCH($A3, All_India_Index_Upto_April23__1___1[#Headers],0) ) ), "")} -> 219.4 | E3: Food | G3: Energy | H3: =AVERAGEIF($E$2:$E$27, G3, $B$2:$B$27) -> 182.8 | I3: =IF(G3="Housing","",AVERAGEIF($E:$E, G3, $C:$C)) -> 182.5 | J3: =AVERAGEIF($E:$E, G3, $D:$D) -> 183.4 | K3: =H3 / SUM($H$2:$H$9) -> 0.12787564 | L3: =IF(I3="","", I3 / SUM($I$2:$I$9)) -> 0.14369464 | M3: =J3 / SUM($J$2:$J$9) -> 0.12985023
A4: Egg | B4: {=IFERROR( _xlfn.XLOOKUP( 1, (All_India_Index_Upto_April23__1___1[Sector]="Rural+Urban") * (All_India_Index_Upto_April23__1___1[Date]=DATE(2023,5,1)), INDEX(All_India_Index_Upto_April23__1___1[],0, MATCH($A4, All_India_Index_Upto_April23__1___1[#Headers],0) ) ), "")} -> 173.2 | C4: {=IFERROR( _xlfn.XLOOKUP( 1, (All_India_Index_Upto_April23__1___1[Sector]="Rural") * (All_India_Index_Upto_April23__1___1[Date]=DATE(2023,5,1)), INDEX(All_India_Index_Upto_April23__1___1[],0, MATCH($A4, All_India_Index_Upto_April23__1___1[#Headers],0) ) ), "")} -> 171 | D4: {=IFERROR( _xlfn.XLOOKUP( 1, (All_India_Index_Upto_April23__1___1[Sector]="Urban") * (All_India_Index_Upto_April23__1___1[Date]=DATE(2023,5,1)), INDEX(All_India_Index_Upto_April23__1___1[],0, MATCH($A4, All_India_Index_Upto_April23__1___1[#Headers],0) ) ), "")} -> 176.7 | E4: Food | G4: Transport | H4: =AVERAGEIF($E$2:$E$27, G4, $B$2:$B$27) -> 164.8 | I4: =IF(G4="Housing","",AVERAGEIF($E:$E, G4, $C:$C)) -> 169.7 | J4: =AVERAGEIF($E:$E, G4, $D:$D) -> 160.4 | K4: =H4 / SUM($H$2:$H$9) -> 0.11528395 | L4: =IF(I4="","", I4 / SUM($I$2:$I$9)) -> 0.13361633 | M4: =J4 / SUM($J$2:$J$9) -> 0.11356585
A5: Milk and products | B5: {=IFERROR( _xlfn.XLOOKUP( 1, (All_India_Index_Upto_April23__1___1[Sector]="Rural+Urban") * (All_India_Index_Upto_April23__1___1[Date]=DATE(2023,5,1)), INDEX(All_India_Index_Upto_April23__1___1[],0, MATCH($A5, All_India_Index_Upto_April23__1___1[#Headers],0) ) ), "")} -> 179.5 | C5: {=IFERROR( _xlfn.XLOOKUP( 1, (All_India_Index_Upto_April23__1___1[Sector]="Rural") * (All_India_Index_Upto_April23__1___1[Date]=DATE(2023,5,1)), INDEX(All_India_Index_Upto_April23__1___1[],0, MATCH($A5, All_India_Index_Upto_April23__1___1[#Headers],0) ) ), "")} -> 179.6 | D5: {=IFERROR( _xlfn.XLOOKUP( 1, (All_India_Index_Upto_April23__1___1[Sector]="Urban") * (All_India_Index_Upto_April23__1___1[Date]=DATE(2023,5,1)), INDEX(All_India_Index_Upto_April23__1___1[],0, MATCH($A5, All_India_Index_Upto_April23__1___1[#Headers],0) ) ), "")} -> 179.4 | E5: Food | G5: Housing | H5: 175.6 | I5: =IF(G5="Housing","",AVERAGEIF($E:$E, G5, $C:$C)) | J5: 175.6 | K5: =H5 / SUM($H$2:$H$9) -> 0.12283896 | L5: =IF(I5="","", I5 / SUM($I$2:$I$9)) | M5: =J5 / SUM($J$2:$J$9) -> 0.1243277
A6: Oils and fats | B6: {=IFERROR( _xlfn.XLOOKUP( 1, (All_India_Index_Upto_April23__1___1[Sector]="Rural+Urban") * (All_India_Index_Upto_April23__1___1[Date]=DATE(2023,5,1)), INDEX(All_India_Index_Upto_April23__1___1[],0, MATCH($A6, All_India_Index_Upto_April23__1___1[#Headers],0) ) ), "")} -> 170 | C6: {=IFERROR( _xlfn.XLOOKUP( 1, (All_India_Index_Upto_April23__1___1[Sector]="Rural") * (All_India_Index_Upto_April23__1___1[Date]=DATE(2023,5,1)), INDEX(All_India_Index_Upto_April23__1___1[],0, MATCH($A6, All_India_Index_Upto_April23__1___1[#Headers],0) ) ), "")} -> 173.3 | D6: {=IFERROR( _xlfn.XLOOKUP( 1, (All_India_Index_Upto_April23__1___1[Sector]="Urban") * (All_India_Index_Upto_April23__1___1[Date]=DATE(2023,5,1)), INDEX(All_India_Index_Upto_April23__1___1[],0, MATCH($A6, All_India_Index_Upto_April23__1___1[#Headers],0) ) ), "")} -> 164.4 | E6: Food | G6: Health | H6: =AVERAGEIF($E$2:$E$27, G6, $B$2:$B$27) -> 185.7 | I6: =IF(G6="Housing","",AVERAGEIF($E:$E, G6, $C:$C)) -> 187.8 | J6: =AVERAGEIF($E:$E, G6, $D:$D) -> 182.2 | K6: =H6 / SUM($H$2:$H$9) -> 0.1299043 | L6: =IF(I6="","", I6 / SUM($I$2:$I$9)) -> 0.14786769 | M6: =J6 / SUM($J$2:$J$9) -> 0.12900061
A7: Fruits | B7: {=IFERROR( _xlfn.XLOOKUP( 1, (All_India_Index_Upto_April23__1___1[Sector]="Rural+Urban") * (All_India_Index_Upto_April23__1___1[Date]=DATE(2023,5,1)), INDEX(All_India_Index_Upto_April23__1___1[],0, MATCH($A7, All_India_Index_Upto_April23__1___1[#Headers],0) ) ), "")} -> 172.2 | C7: {=IFERROR( _xlfn.XLOOKUP( 1, (All_India_Index_Upto_April23__1___1[Sector]="Rural") * (All_India_Index_Upto_April23__1___1[Date]=DATE(2023,5,1)), INDEX(All_India_Index_Upto_April23__1___1[],0, MATCH($A7, All_India_Index_Upto_April23__1___1[#Headers],0) ) ), "")} -> 169 | D7: {=IFERROR( _xlfn.XLOOKUP( 1, (All_India_Index_Upto_April23__1___1[Sector]="Urban") * (All_India_Index_Upto_April23__1___1[Date]=DATE(2023,5,1)), INDEX(All_India_Index_Upto_April23__1___1[],0, MATCH($A7, All_India_Index_Upto_April23__1___1[#Headers],0) ) ), "")} -> 175.8 | E7: Food | G7: Education | H7: =AVERAGEIF($E$2:$E$27, G7, $B$2:$B$27) -> 177.1 | I7: =IF(G7="Housing","",AVERAGEIF($E:$E, G7, $C:$C)) -> 180.3 | J7: =AVERAGEIF($E:$E, G7, $D:$D) -> 174.8 | K7: =H7 / SUM($H$2:$H$9) -> 0.12388827 | L7: =IF(I7="","", I7 / SUM($I$2:$I$9)) -> 0.14196243 | M7: =J7 / SUM($J$2:$J$9) -> 0.12376129
A8: Vegetables | B8: {=IFERROR( _xlfn.XLOOKUP( 1, (All_India_Index_Upto_April23__1___1[Sector]="Rural+Urban") * (All_India_Index_Upto_April23__1___1[Date]=DATE(2023,5,1)), INDEX(All_India_Index_Upto_April23__1___1[],0, MATCH($A8, All_India_Index_Upto_April23__1___1[#Headers],0) ) ), "")} -> 161 | C8: {=IFERROR( _xlfn.XLOOKUP( 1, (All_India_Index_Upto_April23__1___1[Sector]="Rural") * (All_India_Index_Upto_April23__1___1[Date]=DATE(2023,5,1)), INDEX(All_India_Index_Upto_April23__1___1[],0, MATCH($A8, All_India_Index_Upto_April23__1___1[#Headers],0) ) ), "")} -> 148.7 | D8: {=IFERROR( _xlfn.XLOOKUP( 1, (All_India_Index_Upto_April23__1___1[Sector]="Urban") * (All_India_Index_Upto_April23__1___1[Date]=DATE(2023,5,1)), INDEX(All_India_Index_Upto_April23__1___1[],0, MATCH($A8, All_India_Index_Upto_April23__1___1[#Headers],0) ) ), "")} -> 185 | E8: Food | G8: Clothing & Footwear | H8: =AVERAGEIF($E$2:$E$27, G8, $B$2:$B$27) -> 184.4 | I8: =IF(G8="Housing","",AVERAGEIF($E:$E, G8, $C:$C)) -> 189.96667 | J8: =AVERAGEIF($E:$E, G8, $D:$D) -> 176.23333 | K8: =H8 / SUM($H$2:$H$9) -> 0.1289949 | L8: =IF(I8="","", I8 / SUM($I$2:$I$9)) -> 0.14957365 | M8: =J8 / SUM($J$2:$J$9) -> 0.12477611
A9: Pulses and products | B9: {=IFERROR( _xlfn.XLOOKUP( 1, (All_India_Index_Upto_April23__1___1[Sector]="Rural+Urban") * (All_India_Index_Upto_April23__1___1[Date]=DATE(2023,5,1)), INDEX(All_India_Index_Upto_April23__1___1[],0, MATCH($A9, All_India_Index_Upto_April23__1___1[#Headers],0) ) ), "")} -> 175.6 | C9: {=IFERROR( _xlfn.XLOOKUP( 1, (All_India_Index_Upto_April23__1___1[Sector]="Rural") * (All_India_Index_Upto_April23__1___1[Date]=DATE(2023,5,1)), INDEX(All_India_Index_Upto_April23__1___1[],0, MATCH($A9, All_India_Index_Upto_April23__1___1[#Headers],0) ) ), "")} -> 174.9 | D9: {=IFERROR( _xlfn.XLOOKUP( 1, (All_India_Index_Upto_April23__1___1[Sector]="Urban") * (All_India_Index_Upto_April23__1___1[Date]=DATE(2023,5,1)), INDEX(All_India_Index_Upto_April23__1___1[],0, MATCH($A9, All_India_Index_Upto_April23__1___1[#Headers],0) ) ), "")} -> 176.9 | E9: Food | G9: Others | H9: =AVERAGEIF($E$2:$E$27, G9, $B$2:$B$27) -> 181.66 | I9: =IF(G9="Housing","",AVERAGEIF($E:$E, G9, $C:$C)) -> 183.58 | J9: =AVERAGEIF($E:$E, G9, $D:$D) -> 180.14 | K9: =H9 / SUM($H$2:$H$9) -> 0.12707817 | L9: =IF(I9="","", I9 / SUM($I$2:$I$9)) -> 0.14454499 | M9: =J9 / SUM($J$2:$J$9) -> 0.1275421
A10: Sugar and Confectionery | B10: {=IFERROR( _xlfn.XLOOKUP( 1, (All_India_Index_Upto_April23__1___1[Sector]="Rural+Urban") * (All_India_Index_Upto_April23__1___1[Date]=DATE(2023,5,1)), INDEX(All_India_Index_Upto_April23__1___1[],0, MATCH($A10, All_India_Index_Upto_April23__1___1[#Headers],0) ) ), "")} -> 122.7 | C10: {=IFERROR( _xlfn.XLOOKUP( 1, (All_India_Index_Upto_April23__1___1[Sector]="Rural") * (All_India_Index_Upto_April23__1___1[Date]=DATE(2023,5,1)), INDEX(All_India_Index_Upto_April23__1___1[],0, MATCH($A10, All_India_Index_Upto_April23__1___1[#Headers],0) ) ), "")} -> 121.9 | D10: {=IFERROR( _xlfn.XLOOKUP( 1, (All_India_Index_Upto_April23__1___1[Sector]="Urban") * (All_India_Index_Upto_April23__1___1[Date]=DATE(2023,5,1)), INDEX(All_India_Index_Upto_April23__1___1[],0, MATCH($A10, All_India_Index_Upto_April23__1___1[#Headers],0) ) ), "")} -> 124.2 | E10: Food | G10: Total | H10: =SUM(H2:H9) -> 1429.5138 | I10: =SUM(I2:I9) -> 1270.0544 | J10: =SUM(J2:J9) -> 1412.3964 | K10: =H10 / SUM($H$2:$H$9) -> 1 | L10: =IF(I10="","", I10 / SUM($I$2:$I$9)) -> 1 | M10: =J10 / SUM($J$2:$J$9) -> 1
A11: Spices | B11: {=IFERROR( _xlfn.XLOOKUP( 1, (All_India_Index_Upto_April23__1___1[Sector]="Rural+Urban") * (All_India_Index_Upto_April23__1___1[Date]=DATE(2023,5,1)), INDEX(All_India_Index_Upto_April23__1___1[],0, MATCH($A11, All_India_Index_Upto_April23__1___1[#Headers],0) ) ), "")} -> 218 | C11: {=IFERROR( _xlfn.XLOOKUP( 1, (All_India_Index_Upto_April23__1___1[Sector]="Rural") * (All_India_Index_Upto_April23__1___1[Date]=DATE(2023,5,1)), INDEX(All_India_Index_Upto_April23__1___1[],0, MATCH($A11, All_India_Index_Upto_April23__1___1[#Headers],0) ) ), "")} -> 221 | D11: {=IFERROR( _xlfn.XLOOKUP( 1, (All_India_Index_Upto_April23__1___1[Sector]="Urban") * (All_India_Index_Upto_April23__1___1[Date]=DATE(2023,5,1)), INDEX(All_India_Index_Upto_April23__1___1[],0, MATCH($A11, All_India_Index_Upto_April23__1___1[#Headers],0) ) ), "")} -> 211.9 | E11: Food
A12: Non-alcoholic beverages | B12: {=IFERROR( _xlfn.XLOOKUP( 1, (All_India_Index_Upto_April23__1___1[Sector]="Rural+Urban") * (All_India_Index_Upto_April23__1___1[Date]=DATE(2023,5,1)), INDEX(All_India_Index_Upto_April23__1___1[],0, MATCH($A12, All_India_Index_Upto_April23__1___1[#Headers],0) ) ), "")} -> 173.4 | C12: {=IFERROR( _xlfn.XLOOKUP( 1, (All_India_Index_Upto_April23__1___1[Sector]="Rural") * (All_India_Index_Upto_April23__1___1[Date]=DATE(2023,5,1)), INDEX(All_India_Index_Upto_April23__1___1[],0, MATCH($A12, All_India_Index_Upto_April23__1___1[#Headers],0) ) ), "")} -> 178.7 | D12: {=IFERROR( _xlfn.XLOOKUP( 1, (All_India_Index_Upto_April23__1___1[Sector]="Urban") * (All_India_Index_Upto_April23__1___1[Date]=DATE(2023,5,1)), INDEX(All_India_Index_Upto_April23__1___1[],0, MATCH($A12, All_India_Index_Upto_April23__1___1[#Headers],0) ) ), "")} -> 165.9 | E12: Food
A13: Prepared meals, snacks, sweets etc. | B13: {=IFERROR( _xlfn.XLOOKUP( 1, (All_India_Index_Upto_April23__1___1[Sector]="Rural+Urban") * (All_India_Index_Upto_April23__1___1[Date]=DATE(2023,5,1)), INDEX(All_India_Index_Upto_April23__1___1[],0, MATCH($A13, All_India_Index_Upto_April23__1___1[#Headers],0) ) ), "")} -> 194.2 | C13: {=IFERROR( _xlfn.XLOOKUP( 1, (All_India_Index_Upto_April23__1___1[Sector]="Rural") * (All_India_Index_Upto_April23__1___1[Date]=DATE(2023,5,1)), INDEX(All_India_Index_Upto_April23__1___1[],0, MATCH($A13, All_India_Index_Upto_April23__1___1[#Headers],0) ) ), "")} -> 191.1 | D13: {=IFERROR( _xlfn.XLOOKUP( 1, (All_India_Index_Upto_April23__1___1[Sector]="Urban") * (All_India_Index_Upto_April23__1___1[Date]=DATE(2023,5,1)), INDEX(All_India_Index_Upto_April23__1___1[],0, MATCH($A13, All_India_Index_Upto_April23__1___1[#Headers],0) ) ), "")} -> 197.7 | E13: Food
A14: Food and beverages | B14: {=IFERROR( _xlfn.XLOOKUP( 1, (All_India_Index_Upto_April23__1___1[Sector]="Rural+Urban") * (All_India_Index_Upto_April23__1___1[Date]=DATE(2023,5,1)), INDEX(All_India_Index_Upto_April23__1___1[],0, MATCH($A14, All_India_Index_Upto_April23__1___1[#Headers],0) ) ), "")} -> 179.1 | C14: {=IFERROR( _xlfn.XLOOKUP( 1, (All_India_Index_Upto_April23__1___1[Sector]="Rural") * (All_India_Index_Upto_April23__1___1[Date]=DATE(2023,5,1)), INDEX(All_India_Index_Upto_April23__1___1[],0, MATCH($A14, All_India_Index_Upto_April23__1___1[#Headers],0) ) ), "")} -> 176.8 | D14: {=IFERROR( _xlfn.XLOOKUP( 1, (All_India_Index_Upto_April23__1___1[Sector]="Urban") * (All_India_Index_Upto_April23__1___1[Date]=DATE(2023,5,1)), INDEX(All_India_Index_Upto_April23__1___1[],0, MATCH($A14, All_India_Index_Upto_April23__1___1[#Headers],0) ) ), "")} -> 183.1 | E14: Food
A15: Pan, tobacco and intoxicants | B15: {=IFERROR( _xlfn.XLOOKUP( 1, (All_India_Index_Upto_April23__1___1[Sector]="Rural+Urban") * (All_India_Index_Upto_April23__1___1[Date]=DATE(2023,5,1)), INDEX(All_India_Index_Upto_April23__1___1[],0, MATCH($A15, All_India_Index_Upto_April23__1___1[#Headers],0) ) ), "")} -> 201 | C15: {=IFERROR( _xlfn.XLOOKUP( 1, (All_India_Index_Upto_April23__1___1[Sector]="Rural") * (All_India_Index_Upto_April23__1___1[Date]=DATE(2023,5,1)), INDEX(All_India_Index_Upto_April23__1___1[],0, MATCH($A15, All_India_Index_Upto_April23__1___1[#Headers],0) ) ), "")} -> 199.9 | D15: {=IFERROR( _xlfn.XLOOKUP( 1, (All_India_Index_Upto_April23__1___1[Sector]="Urban") * (All_India_Index_Upto_April23__1___1[Date]=DATE(2023,5,1)), INDEX(All_India_Index_Upto_April23__1___1[],0, MATCH($A15, All_India_Index_Upto_April23__1___1[#Headers],0) ) ), "")} -> 204.2 | E15: Others
A16: Clothing | B16: {=IFERROR( _xlfn.XLOOKUP( 1, (All_India_Index_Upto_April23__1___1[Sector]="Rural+Urban") * (All_India_Index_Upto_April23__1___1[Date]=DATE(2023,5,1)), INDEX(All_India_Index_Upto_April23__1___1[],0, MATCH($A16, All_India_Index_Upto_April23__1___1[#Headers],0) ) ), "")} -> 187.3 | C16: {=IFERROR( _xlfn.XLOOKUP( 1, (All_India_Index_Upto_April23__1___1[Sector]="Rural") * (All_India_Index_Upto_April23__1___1[Date]=DATE(2023,5,1)), INDEX(All_India_Index_Upto_April23__1___1[],0, MATCH($A16, All_India_Index_Upto_April23__1___1[#Headers],0) ) ), "")} -> 191.2 | D16: {=IFERROR( _xlfn.XLOOKUP( 1, (All_India_Index_Upto_April23__1___1[Sector]="Urban") * (All_India_Index_Upto_April23__1___1[Date]=DATE(2023,5,1)), INDEX(All_India_Index_Upto_April23__1___1[],0, MATCH($A16, All_India_Index_Upto_April23__1___1[#Headers],0) ) ), "")} -> 181.3 | E16: Clothing & Footwear
A17: Footwear | B17: {=IFERROR( _xlfn.XLOOKUP( 1, (All_India_Index_Upto_April23__1___1[Sector]="Rural+Urban") * (All_India_Index_Upto_April23__1___1[Date]=DATE(2023,5,1)), INDEX(All_India_Index_Upto_April23__1___1[],0, MATCH($A17, All_India_Index_Upto_April23__1___1[#Headers],0) ) ), "")} -> 179.7 | C17: {=IFERROR( _xlfn.XLOOKUP( 1, (All_India_Index_Upto_April23__1___1[Sector]="Rural") * (All_India_Index_Upto_April23__1___1[Date]=DATE(2023,5,1)), INDEX(All_India_Index_Upto_April23__1___1[],0, MATCH($A17, All_India_Index_Upto_April23__1___1[#Headers],0) ) ), "")} -> 187.9 | D17: {=IFERROR( _xlfn.XLOOKUP( 1, (All_India_Index_Upto_April23__1___1[Sector]="Urban") * (All_India_Index_Upto_April23__1___1[Date]=DATE(2023,5,1)), INDEX(All_India_Index_Upto_April23__1___1[],0, MATCH($A17, All_India_Index_Upto_April23__1___1[#Headers],0) ) ), "")} -> 168.1 | E17: Clothing & Footwear
A18: Clothing and footwear | B18: {=IFERROR( _xlfn.XLOOKUP( 1, (All_India_Index_Upto_April23__1___1[Sector]="Rural+Urban") * (All_India_Index_Upto_April23__1___1[Date]=DATE(2023,5,1)), INDEX(All_India_Index_Upto_April23__1___1[],0, MATCH($A18, All_India_Index_Upto_April23__1___1[#Headers],0) ) ), "")} -> 186.2 | C18: {=IFERROR( _xlfn.XLOOKUP( 1, (All_India_Index_Upto_April23__1___1[Sector]="Rural") * (All_India_Index_Upto_April23__1___1[Date]=DATE(2023,5,1)), INDEX(All_India_Index_Upto_April23__1___1[],0, MATCH($A18, All_India_Index_Upto_April23__1___1[#Headers],0) ) ), "")} -> 190.8 | D18: {=IFERROR( _xlfn.XLOOKUP( 1, (All_India_Index_Upto_April23__1___1[Sector]="Urban") * (All_India_Index_Upto_April23__1___1[Date]=DATE(2023,5,1)), INDEX(All_India_Index_Upto_April23__1___1[],0, MATCH($A18, All_India_Index_Upto_April23__1___1[#Headers],0) ) ), "")} -> 179.3 | E18: Clothing & Footwear
A19: Housing | B19: {=IFERROR( _xlfn.XLOOKUP( 1, (All_India_Index_Upto_April23__1___1[Sector]="Rural+Urban") * (All_India_Index_Upto_April23__1___1[Date]=DATE(2023,5,1)), INDEX(All_India_Index_Upto_April23__1___1[],0, MATCH($A19, All_India_Index_Upto_April23__1___1[#Headers],0) ) ), "")} -> 175.6 | D19: {=IFERROR( _xlfn.XLOOKUP( 1, (All_India_Index_Upto_April23__1___1[Sector]="Urban") * (All_India_Index_Upto_April23__1___1[Date]=DATE(2023,5,1)), INDEX(All_India_Index_Upto_April23__1___1[],0, MATCH($A19, All_India_Index_Upto_April23__1___1[#Headers],0) ) ), "")} -> 175.6 | E19: Housing
A20: Fuel and light | B20: {=IFERROR( _xlfn.XLOOKUP( 1, (All_India_Index_Upto_April23__1___1[Sector]="Rural+Urban") * (All_India_Index_Upto_April23__1___1[Date]=DATE(2023,5,1)), INDEX(All_India_Index_Upto_April23__1___1[],0, MATCH($A20, All_India_Index_Upto_April23__1___1[#Headers],0) ) ), "")} -> 182.8 | C20: {=IFERROR( _xlfn.XLOOKUP( 1, (All_India_Index_Upto_April23__1___1[Sector]="Rural") * (All_India_Index_Upto_April23__1___1[Date]=DATE(2023,5,1)), INDEX(All_India_Index_Upto_April23__1___1[],0, MATCH($A20, All_India_Index_Upto_April23__1___1[#Headers],0) ) ), "")} -> 182.5 | D20: {=IFERROR( _xlfn.XLOOKUP( 1, (All_India_Index_Upto_April23__1___1[Sector]="Urban") * (All_India_Index_Upto_April23__1___1[Date]=DATE(2023,5,1)), INDEX(All_India_Index_Upto_April23__1___1[],0, MATCH($A20, All_India_Index_Upto_April23__1___1[#Headers],0) ) ), "")} -> 183.4 | E20: Energy
A21: Household goods and services | B21: {=IFERROR( _xlfn.XLOOKUP( 1, (All_India_Index_Upto_April23__1___1[Sector]="Rural+Urban") * (All_India_Index_Upto_April23__1___1[Date]=DATE(2023,5,1)), INDEX(All_India_Index_Upto_April23__1___1[],0, MATCH($A21, All_India_Index_Upto_April23__1___1[#Headers],0) ) ), "")} -> 175.2 | C21: {=IFERROR( _xlfn.XLOOKUP( 1, (All_India_Index_Upto_April23__1___1[Sector]="Rural") * (All_India_Index_Upto_April23__1___1[Date]=DATE(2023,5,1)), INDEX(All_India_Index_Upto_April23__1___1[],0, MATCH($A21, All_India_Index_Upto_April23__1___1[#Headers],0) ) ), "")} -> 179.8 | D21: {=IFERROR( _xlfn.XLOOKUP( 1, (All_India_Index_Upto_April23__1___1[Sector]="Urban") * (All_India_Index_Upto_April23__1___1[Date]=DATE(2023,5,1)), INDEX(All_India_Index_Upto_April23__1___1[],0, MATCH($A21, All_India_Index_Upto_April23__1___1[#Headers],0) ) ), "")} -> 170.1 | E21: Others
A22: Health | B22: {=IFERROR( _xlfn.XLOOKUP( 1, (All_India_Index_Upto_April23__1___1[Sector]="Rural+Urban") * (All_India_Index_Upto_April23__1___1[Date]=DATE(2023,5,1)), INDEX(All_India_Index_Upto_April23__1___1[],0, MATCH($A22, All_India_Index_Upto_April23__1___1[#Headers],0) ) ), "")} -> 185.7 | C22: {=IFERROR( _xlfn.XLOOKUP( 1, (All_India_Index_Upto_April23__1___1[Sector]="Rural") * (All_India_Index_Upto_April23__1___1[Date]=DATE(2023,5,1)), INDEX(All_India_Index_Upto_April23__1___1[],0, MATCH($A22, All_India_Index_Upto_April23__1___1[#Headers],0) ) ), "")} -> 187.8 | D22: {=IFERROR( _xlfn.XLOOKUP( 1, (All_India_Index_Upto_April23__1___1[Sector]="Urban") * (All_India_Index_Upto_April23__1___1[Date]=DATE(2023,5,1)), INDEX(All_India_Index_Upto_April23__1___1[],0, MATCH($A22, All_India_Index_Upto_April23__1___1[#Headers],0) ) ), "")} -> 182.2 | E22: Health
A23: Transport and communication | B23: {=IFERROR( _xlfn.XLOOKUP( 1, (All_India_Index_Upto_April23__1___1[Sector]="Rural+Urban") * (All_India_Index_Upto_April23__1___1[Date]=DATE(2023,5,1)), INDEX(All_India_Index_Upto_April23__1___1[],0, MATCH($A23, All_India_Index_Upto_April23__1___1[#Headers],0) ) ), "")} -> 164.8 | C23: {=IFERROR( _xlfn.XLOOKUP( 1, (All_India_Index_Upto_April23__1___1[Sector]="Rural") * (All_India_Index_Upto_April23__1___1[Date]=DATE(2023,5,1)), INDEX(All_India_Index_Upto_April23__1___1[],0, MATCH($A23, All_India_Index_Upto_April23__1___1[#Headers],0) ) ), "")} -> 169.7 | D23: {=IFERROR( _xlfn.XLOOKUP( 1, (All_India_Index_Upto_April23__1___1[Sector]="Urban") * (All_India_Index_Upto_April23__1___1[Date]=DATE(2023,5,1)), INDEX(All_India_Index_Upto_April23__1___1[],0, MATCH($A23, All_India_Index_Upto_April23__1___1[#Headers],0) ) ), "")} -> 160.4 | E23: Transport
A24: Recreation and amusement | B24: {=IFERROR( _xlfn.XLOOKUP( 1, (All_India_Index_Upto_April23__1___1[Sector]="Rural+Urban") * (All_India_Index_Upto_April23__1___1[Date]=DATE(2023,5,1)), INDEX(All_India_Index_Upto_April23__1___1[],0, MATCH($A24, All_India_Index_Upto_April23__1___1[#Headers],0) ) ), "")} -> 171.2 | C24: {=IFERROR( _xlfn.XLOOKUP( 1, (All_India_Index_Upto_April23__1___1[Sector]="Rural") * (All_India_Index_Upto_April23__1___1[Date]=DATE(2023,5,1)), INDEX(All_India_Index_Upto_April23__1___1[],0, MATCH($A24, All_India_Index_Upto_April23__1___1[#Headers],0) ) ), "")} -> 173.8 | D24: {=IFERROR( _xlfn.XLOOKUP( 1, (All_India_Index_Upto_April23__1___1[Sector]="Urban") * (All_India_Index_Upto_April23__1___1[Date]=DATE(2023,5,1)), INDEX(All_India_Index_Upto_April23__1___1[],0, MATCH($A24, All_India_Index_Upto_April23__1___1[#Headers],0) ) ), "")} -> 169.2 | E24: Others
A25: Education | B25: {=IFERROR( _xlfn.XLOOKUP( 1, (All_India_Index_Upto_April23__1___1[Sector]="Rural+Urban") * (All_India_Index_Upto_April23__1___1[Date]=DATE(2023,5,1)), INDEX(All_India_Index_Upto_April23__1___1[],0, MATCH($A25, All_India_Index_Upto_April23__1___1[#Headers],0) ) ), "")} -> 177.1 | C25: {=IFERROR( _xlfn.XLOOKUP( 1, (All_India_Index_Upto_April23__1___1[Sector]="Rural") * (All_India_Index_Upto_April23__1___1[Date]=DATE(2023,5,1)), INDEX(All_India_Index_Upto_April23__1___1[],0, MATCH($A25, All_India_Index_Upto_April23__1___1[#Headers],0) ) ), "")} -> 180.3 | D25: {=IFERROR( _xlfn.XLOOKUP( 1, (All_India_Index_Upto_April23__1___1[Sector]="Urban") * (All_India_Index_Upto_April23__1___1[Date]=DATE(2023,5,1)), INDEX(All_India_Index_Upto_April23__1___1[],0, MATCH($A25, All_India_Index_Upto_April23__1___1[#Headers],0) ) ), "")} -> 174.8 | E25: Education
A26: Personal care and effects | B26: {=IFERROR( _xlfn.XLOOKUP( 1, (All_India_Index_Upto_April23__1___1[Sector]="Rural+Urban") * (All_India_Index_Upto_April23__1___1[Date]=DATE(2023,5,1)), INDEX(All_India_Index_Upto_April23__1___1[],0, MATCH($A26, All_India_Index_Upto_April23__1___1[#Headers],0) ) ), "")} -> 185.2 | C26: {=IFERROR( _xlfn.XLOOKUP( 1, (All_India_Index_Upto_April23__1___1[Sector]="Rural") * (All_India_Index_Upto_April23__1___1[Date]=DATE(2023,5,1)), INDEX(All_India_Index_Upto_April23__1___1[],0, MATCH($A26, All_India_Index_Upto_April23__1___1[#Headers],0) ) ), "")} -> 184.9 | D26: {=IFERROR( _xlfn.XLOOKUP( 1, (All_India_Index_Upto_April23__1___1[Sector]="Urban") * (All_India_Index_Upto_April23__1___1[Date]=DATE(2023,5,1)), INDEX(All_India_Index_Upto_April23__1___1[],0, MATCH($A26, All_India_Index_Upto_April23__1___1[#Headers],0) ) ), "")} -> 185.6 | E26: Others
A27: Miscellaneous | B27: {=IFERROR( _xlfn.XLOOKUP( 1, (All_India_Index_Upto_April23__1___1[Sector]="Rural+Urban") * (All_India_Index_Upto_April23__1___1[Date]=DATE(2023,5,1)), INDEX(All_India_Index_Upto_April23__1___1[],0, MATCH($A27, All_India_Index_Upto_April23__1___1[#Headers],0) ) ), "")} -> 175.7 | C27: {=IFERROR( _xlfn.XLOOKUP( 1, (All_India_Index_Upto_April23__1___1[Sector]="Rural") * (All_India_Index_Upto_April23__1___1[Date]=DATE(2023,5,1)), INDEX(All_India_Index_Upto_April23__1___1[],0, MATCH($A27, All_India_Index_Upto_April23__1___1[#Headers],0) ) ), "")} -> 179.5 | D27: {=IFERROR( _xlfn.XLOOKUP( 1, (All_India_Index_Upto_April23__1___1[Sector]="Urban") * (All_India_Index_Upto_April23__1___1[Date]=DATE(2023,5,1)), INDEX(All_India_Index_Upto_April23__1___1[],0, MATCH($A27, All_India_Index_Upto_April23__1___1[#Headers],0) ) ), "")} -> 171.6 | E27: Others

Sheet Sheet7
A1: Date | B1: Year | C1: Month | D1: General Index (Rural + Urban) | E1: Prev Year Index | F1: MoM Inflation % | H1: Year | I1: Avg YoY Inflation %
A2: 42736 | B2: =YEAR(A2) -> 2017 | C2: =MONTH(A2) -> 1 | D2: {=IFERROR( INDEX( All_India_Index_Upto_April23__1___1[General index], MATCH( 1, (All_India_Index_Upto_April23__1___1[Sector]="Rural+Urban") * (All_India_Index_Upto_April23__1___1[Date]=A2), 0 ) ), "")} -> 130.3 | E2: {=IFERROR( INDEX( All_India_Index_Upto_April23__1___1[General index], MATCH( 1, (All_India_Index_Upto_April23__1___1[Sector]="Rural+Urban") * (All_India_Index_Upto_April23__1___1[Date]=DATE(YEAR(A2)-1, MONTH(A2), 1)), 0 ) ), "")} -> 126.3 | F2: =IFERROR( (D2-E2)/E2, "") -> 0.031670625 | H2: 2017 | I2: =AVERAGEIFS($F:$F, $B:$B, H2) -> 0.033273885
A3: 42767 | B3: =YEAR(A3) -> 2017 | C3: =MONTH(A3) -> 2 | D3: {=IFERROR( INDEX( All_India_Index_Upto_April23__1___1[General index], MATCH( 1, (All_India_Index_Upto_April23__1___1[Sector]="Rural+Urban") * (All_India_Index_Upto_April23__1___1[Date]=A3), 0 ) ), "")} -> 130.6 | E3: {=IFERROR( INDEX( All_India_Index_Upto_April23__1___1[General index], MATCH( 1, (All_India_Index_Upto_April23__1___1[Sector]="Rural+Urban") * (All_India_Index_Upto_April23__1___1[Date]=DATE(YEAR(A3)-1, MONTH(A3), 1)), 0 ) ), "")} -> 126 | F3: =IFERROR( (D3-E3)/E3, "") -> 0.036507937 | H3: 2018 | I3: =AVERAGEIFS($F:$F, $B:$B, H3) -> 0.039676972
A4: 42795 | B4: =YEAR(A4) -> 2017 | C4: =MONTH(A4) -> 3 | D4: {=IFERROR( INDEX( All_India_Index_Upto_April23__1___1[General index], MATCH( 1, (All_India_Index_Upto_April23__1___1[Sector]="Rural+Urban") * (All_India_Index_Upto_April23__1___1[Date]=A4), 0 ) ), "")} -> 130.9 | E4: {=IFERROR( INDEX( All_India_Index_Upto_April23__1___1[General index], MATCH( 1, (All_India_Index_Upto_April23__1___1[Sector]="Rural+Urban") * (All_India_Index_Upto_April23__1___1[Date]=DATE(YEAR(A4)-1, MONTH(A4), 1)), 0 ) ), "")} -> 126 | F4: =IFERROR( (D4-E4)/E4, "") -> 0.038888889 | H4: 2019 | I4: =AVERAGEIFS($F:$F, $B:$B, H4) -> 0.037704798
A5: 42826 | B5: =YEAR(A5) -> 2017 | C5: =MONTH(A5) -> 4 | D5: {=IFERROR( INDEX( All_India_Index_Upto_April23__1___1[General index], MATCH( 1, (All_India_Index_Upto_April23__1___1[Sector]="Rural+Urban") * (All_India_Index_Upto_April23__1___1[Date]=A5), 0 ) ), "")} -> 131.1 | E5: {=IFERROR( INDEX( All_India_Index_Upto_April23__1___1[General index], MATCH( 1, (All_India_Index_Upto_April23__1___1[Sector]="Rural+Urban") * (All_India_Index_Upto_April23__1___1[Date]=DATE(YEAR(A5)-1, MONTH(A5), 1)), 0 ) ), "")} -> 127.3 | F5: =IFERROR( (D5-E5)/E5, "") -> 0.029850746 | H5: 2020 | I5: =AVERAGEIFS($F:$F, $B:$B, H5) -> 0.062670091
A6: 42856 | B6: =YEAR(A6) -> 2017 | C6: =MONTH(A6) -> 5 | D6: {=IFERROR( INDEX( All_India_Index_Upto_April23__1___1[General index], MATCH( 1, (All_India_Index_Upto_April23__1___1[Sector]="Rural+Urban") * (All_India_Index_Upto_April23__1___1[Date]=A6), 0 ) ), "")} -> 131.4 | E6: {=IFERROR( INDEX( All_India_Index_Upto_April23__1___1[General index], MATCH( 1, (All_India_Index_Upto_April23__1___1[Sector]="Rural+Urban") * (All_India_Index_Upto_April23__1___1[Date]=DATE(YEAR(A6)-1, MONTH(A6), 1)), 0 ) ), "")} -> 128.6 | F6: =IFERROR( (D6-E6)/E6, "") -> 0.021772939 | H6: 2021 | I6: =AVERAGEIFS($F:$F, $B:$B, H6) -> 0.053818467
A7: 42887 | B7: =YEAR(A7) -> 2017 | C7: =MONTH(A7) -> 6 | D7: {=IFERROR( INDEX( All_India_Index_Upto_April23__1___1[General index], MATCH( 1, (All_India_Index_Upto_April23__1___1[Sector]="Rural+Urban") * (All_India_Index_Upto_April23__1___1[Date]=A7), 0 ) ), "")} -> 132 | E7: {=IFERROR( INDEX( All_India_Index_Upto_April23__1___1[General index], MATCH( 1, (All_India_Index_Upto_April23__1___1[Sector]="Rural+Urban") * (All_India_Index_Upto_April23__1___1[Date]=DATE(YEAR(A7)-1, MONTH(A7), 1)), 0 ) ), "")} -> 130.1 | F7: =IFERROR( (D7-E7)/E7, "") -> 0.014604151 | H7: 2022 | I7: =AVERAGEIFS($F:$F, $B:$B, H7) -> 0.06624065
A8: 42917 | B8: =YEAR(A8) -> 2017 | C8: =MONTH(A8) -> 7 | D8: {=IFERROR( INDEX( All_India_Index_Upto_April23__1___1[General index], MATCH( 1, (All_India_Index_Upto_April23__1___1[Sector]="Rural+Urban") * (All_India_Index_Upto_April23__1___1[Date]=A8), 0 ) ), "")} -> 134.2 | E8: {=IFERROR( INDEX( All_India_Index_Upto_April23__1___1[General index], MATCH( 1, (All_India_Index_Upto_April23__1___1[Sector]="Rural+Urban") * (All_India_Index_Upto_April23__1___1[Date]=DATE(YEAR(A8)-1, MONTH(A8), 1)), 0 ) ), "")} -> 131.1 | F8: =IFERROR( (D8-E8)/E8, "") -> 0.023646072 | H8: 2023 | I8: =AVERAGEIFS($F:$F, $B:$B, H8) -> 0.055756722
A9: 42948 | B9: =YEAR(A9) -> 2017 | C9: =MONTH(A9) -> 8 | D9: {=IFERROR( INDEX( All_India_Index_Upto_April23__1___1[General index], MATCH( 1, (All_India_Index_Upto_April23__1___1[Sector]="Rural+Urban") * (All_India_Index_Upto_April23__1___1[Date]=A9), 0 ) ), "")} -> 135.4 | E9: {=IFERROR( INDEX( All_India_Index_Upto_April23__1___1[General index], MATCH( 1, (All_India_Index_Upto_April23__1___1[Sector]="Rural+Urban") * (All_India_Index_Upto_April23__1___1[Date]=DATE(YEAR(A9)-1, MONTH(A9), 1)), 0 ) ), "")} -> 131.1 | F9: =IFERROR( (D9-E9)/E9, "") -> 0.03279939
